[2022-10-03 20:36:42,531] {taskinstance.py:1032} INFO - Dependencies all met for <TaskInstance: ingest_star_wars.create_people_table scheduled__2022-10-03T00:00:00+00:00 [queued]>
[2022-10-03 20:36:42,583] {taskinstance.py:1032} INFO - Dependencies all met for <TaskInstance: ingest_star_wars.create_people_table scheduled__2022-10-03T00:00:00+00:00 [queued]>
[2022-10-03 20:36:42,604] {taskinstance.py:1238} INFO - 
--------------------------------------------------------------------------------
[2022-10-03 20:36:42,606] {taskinstance.py:1239} INFO - Starting attempt 1 of 1
[2022-10-03 20:36:42,608] {taskinstance.py:1240} INFO - 
--------------------------------------------------------------------------------
[2022-10-03 20:36:42,700] {taskinstance.py:1259} INFO - Executing <Task(PostgresOperator): create_people_table> on 2022-10-03 00:00:00+00:00
[2022-10-03 20:36:42,711] {standard_task_runner.py:52} INFO - Started process 1717 to run task
[2022-10-03 20:36:42,729] {standard_task_runner.py:76} INFO - Running: ['***', 'tasks', 'run', 'ingest_star_wars', 'create_people_table', 'scheduled__2022-10-03T00:00:00+00:00', '--job-id', '9', '--raw', '--subdir', 'DAGS_FOLDER/ingest_starwars_data.py', '--cfg-path', '/tmp/tmp113alevu', '--error-file', '/tmp/tmpt30nc7q7']
[2022-10-03 20:36:42,742] {standard_task_runner.py:77} INFO - Job 9: Subtask create_people_table
[2022-10-03 20:36:42,945] {logging_mixin.py:109} INFO - Running <TaskInstance: ingest_star_wars.create_people_table scheduled__2022-10-03T00:00:00+00:00 [running]> on host 86c7e9112604
[2022-10-03 20:36:43,284] {taskinstance.py:1426} INFO - Exporting the following env vars:
AIRFLOW_CTX_DAG_EMAIL=xxxx@xxxxx.com
AIRFLOW_CTX_DAG_OWNER=Ram
AIRFLOW_CTX_DAG_ID=ingest_star_wars
AIRFLOW_CTX_TASK_ID=create_people_table
AIRFLOW_CTX_EXECUTION_DATE=2022-10-03T00:00:00+00:00
AIRFLOW_CTX_DAG_RUN_ID=scheduled__2022-10-03T00:00:00+00:00
[2022-10-03 20:36:43,319] {base.py:79} INFO - Using connection to: id: postgres_local. Host: host.docker.internal, Port: 5432, Schema: public, Login: postgres, Password: ***, extra: {}
[2022-10-03 20:36:43,439] {taskinstance.py:1700} ERROR - Task failed with exception
Traceback (most recent call last):
  File "/home/airflow/.local/lib/python3.7/site-packages/airflow/models/taskinstance.py", line 1329, in _run_raw_task
    self._execute_task_with_callbacks(context)
  File "/home/airflow/.local/lib/python3.7/site-packages/airflow/models/taskinstance.py", line 1455, in _execute_task_with_callbacks
    result = self._execute_task(context, self.task)
  File "/home/airflow/.local/lib/python3.7/site-packages/airflow/models/taskinstance.py", line 1511, in _execute_task
    result = execute_callable(context=context)
  File "/home/airflow/.local/lib/python3.7/site-packages/airflow/providers/postgres/operators/postgres.py", line 69, in execute
    self.hook.run(self.sql, self.autocommit, parameters=self.parameters)
  File "/home/airflow/.local/lib/python3.7/site-packages/airflow/hooks/dbapi.py", line 198, in run
    with closing(self.get_conn()) as conn:
  File "/home/airflow/.local/lib/python3.7/site-packages/airflow/providers/postgres/hooks/postgres.py", line 115, in get_conn
    self.conn = psycopg2.connect(**conn_args)
  File "/home/airflow/.local/lib/python3.7/site-packages/psycopg2/__init__.py", line 122, in connect
    conn = _connect(dsn, connection_factory=connection_factory, **kwasync)
psycopg2.OperationalError: connection to server at "host.docker.internal" (192.168.65.2), port 5432 failed: FATAL:  database "public" does not exist

[2022-10-03 20:36:43,488] {taskinstance.py:1277} INFO - Marking task as FAILED. dag_id=ingest_star_wars, task_id=create_people_table, execution_date=20221003T000000, start_date=20221003T203642, end_date=20221003T203643
[2022-10-03 20:36:43,559] {standard_task_runner.py:92} ERROR - Failed to execute job 9 for task create_people_table
Traceback (most recent call last):
  File "/home/airflow/.local/lib/python3.7/site-packages/airflow/task/task_runner/standard_task_runner.py", line 85, in _start_by_fork
    args.func(args, dag=self.dag)
  File "/home/airflow/.local/lib/python3.7/site-packages/airflow/cli/cli_parser.py", line 48, in command
    return func(*args, **kwargs)
  File "/home/airflow/.local/lib/python3.7/site-packages/airflow/utils/cli.py", line 92, in wrapper
    return f(*args, **kwargs)
  File "/home/airflow/.local/lib/python3.7/site-packages/airflow/cli/commands/task_command.py", line 298, in task_run
    _run_task_by_selected_method(args, dag, ti)
  File "/home/airflow/.local/lib/python3.7/site-packages/airflow/cli/commands/task_command.py", line 107, in _run_task_by_selected_method
    _run_raw_task(args, ti)
  File "/home/airflow/.local/lib/python3.7/site-packages/airflow/cli/commands/task_command.py", line 184, in _run_raw_task
    error_file=args.error_file,
  File "/home/airflow/.local/lib/python3.7/site-packages/airflow/utils/session.py", line 70, in wrapper
    return func(*args, session=session, **kwargs)
  File "/home/airflow/.local/lib/python3.7/site-packages/airflow/models/taskinstance.py", line 1329, in _run_raw_task
    self._execute_task_with_callbacks(context)
  File "/home/airflow/.local/lib/python3.7/site-packages/airflow/models/taskinstance.py", line 1455, in _execute_task_with_callbacks
    result = self._execute_task(context, self.task)
  File "/home/airflow/.local/lib/python3.7/site-packages/airflow/models/taskinstance.py", line 1511, in _execute_task
    result = execute_callable(context=context)
  File "/home/airflow/.local/lib/python3.7/site-packages/airflow/providers/postgres/operators/postgres.py", line 69, in execute
    self.hook.run(self.sql, self.autocommit, parameters=self.parameters)
  File "/home/airflow/.local/lib/python3.7/site-packages/airflow/hooks/dbapi.py", line 198, in run
    with closing(self.get_conn()) as conn:
  File "/home/airflow/.local/lib/python3.7/site-packages/airflow/providers/postgres/hooks/postgres.py", line 115, in get_conn
    self.conn = psycopg2.connect(**conn_args)
  File "/home/airflow/.local/lib/python3.7/site-packages/psycopg2/__init__.py", line 122, in connect
    conn = _connect(dsn, connection_factory=connection_factory, **kwasync)
psycopg2.OperationalError: connection to server at "host.docker.internal" (192.168.65.2), port 5432 failed: FATAL:  database "public" does not exist

[2022-10-03 20:36:43,651] {local_task_job.py:154} INFO - Task exited with return code 1
[2022-10-03 20:36:44,072] {local_task_job.py:264} INFO - 0 downstream tasks scheduled from follow-on schedule check
[2022-10-04 13:29:43,437] {taskinstance.py:1032} INFO - Dependencies all met for <TaskInstance: ingest_star_wars.create_people_table scheduled__2022-10-03T00:00:00+00:00 [queued]>
[2022-10-04 13:29:43,458] {taskinstance.py:1032} INFO - Dependencies all met for <TaskInstance: ingest_star_wars.create_people_table scheduled__2022-10-03T00:00:00+00:00 [queued]>
[2022-10-04 13:29:43,459] {taskinstance.py:1238} INFO - 
--------------------------------------------------------------------------------
[2022-10-04 13:29:43,460] {taskinstance.py:1239} INFO - Starting attempt 1 of 1
[2022-10-04 13:29:43,461] {taskinstance.py:1240} INFO - 
--------------------------------------------------------------------------------
[2022-10-04 13:29:43,482] {taskinstance.py:1259} INFO - Executing <Task(PostgresOperator): create_people_table> on 2022-10-03 00:00:00+00:00
[2022-10-04 13:29:43,488] {standard_task_runner.py:52} INFO - Started process 3875 to run task
[2022-10-04 13:29:43,493] {standard_task_runner.py:76} INFO - Running: ['***', 'tasks', 'run', 'ingest_star_wars', 'create_people_table', 'scheduled__2022-10-03T00:00:00+00:00', '--job-id', '39', '--raw', '--subdir', 'DAGS_FOLDER/ingest_starwars_data.py', '--cfg-path', '/tmp/tmphs2h78tv', '--error-file', '/tmp/tmpgp8vfozt']
[2022-10-04 13:29:43,494] {standard_task_runner.py:77} INFO - Job 39: Subtask create_people_table
[2022-10-04 13:29:43,575] {logging_mixin.py:109} INFO - Running <TaskInstance: ingest_star_wars.create_people_table scheduled__2022-10-03T00:00:00+00:00 [running]> on host be1a5b89e146
[2022-10-04 13:29:43,680] {taskinstance.py:1426} INFO - Exporting the following env vars:
AIRFLOW_CTX_DAG_EMAIL=xxxx@xxxxx.com
AIRFLOW_CTX_DAG_OWNER=Ram
AIRFLOW_CTX_DAG_ID=ingest_star_wars
AIRFLOW_CTX_TASK_ID=create_people_table
AIRFLOW_CTX_EXECUTION_DATE=2022-10-03T00:00:00+00:00
AIRFLOW_CTX_DAG_RUN_ID=scheduled__2022-10-03T00:00:00+00:00
[2022-10-04 13:29:43,692] {base.py:79} INFO - Using connection to: id: postgres_local. Host: host.docker.internal, Port: 5432, Schema: postgres, Login: postgres, Password: ***, extra: {}
[2022-10-04 13:29:43,760] {dbapi.py:225} INFO - Running statement: CREATE TABLE IF NOT EXISTS star_wars_people (
            name TEXT,
            height TEXT,
            mass TEXT,
            hair_color TEXT,
            skin_color TEXT,
            eye_color TEXT,
            birth_year TEXT,
            gender TEXT,
            homeworld TEXT,
            films TEXT,
            species TEXT,
            vehicles TEXT,
            starships TEXT,
            created TEXT,
            edited TEXT,
            url TEXT
            );, parameters: None
[2022-10-04 13:29:43,766] {postgres.py:71} INFO - NOTICE:  relation "star_wars_people" already exists, skipping

[2022-10-04 13:29:43,800] {taskinstance.py:1277} INFO - Marking task as SUCCESS. dag_id=ingest_star_wars, task_id=create_people_table, execution_date=20221003T000000, start_date=20221004T132943, end_date=20221004T132943
[2022-10-04 13:29:43,882] {local_task_job.py:154} INFO - Task exited with return code 0
[2022-10-04 13:29:43,940] {local_task_job.py:264} INFO - 1 downstream tasks scheduled from follow-on schedule check
