[2022-10-03 20:01:13,965] {taskinstance.py:1032} INFO - Dependencies all met for <TaskInstance: ingest_star_wars.create_people_table scheduled__2022-10-02T14:17:00+00:00 [queued]>
[2022-10-03 20:01:13,982] {taskinstance.py:1032} INFO - Dependencies all met for <TaskInstance: ingest_star_wars.create_people_table scheduled__2022-10-02T14:17:00+00:00 [queued]>
[2022-10-03 20:01:13,983] {taskinstance.py:1238} INFO - 
--------------------------------------------------------------------------------
[2022-10-03 20:01:13,985] {taskinstance.py:1239} INFO - Starting attempt 1 of 1
[2022-10-03 20:01:13,986] {taskinstance.py:1240} INFO - 
--------------------------------------------------------------------------------
[2022-10-03 20:01:14,003] {taskinstance.py:1259} INFO - Executing <Task(PostgresOperator): create_people_table> on 2022-10-02 14:17:00+00:00
[2022-10-03 20:01:14,010] {standard_task_runner.py:52} INFO - Started process 247 to run task
[2022-10-03 20:01:14,014] {standard_task_runner.py:76} INFO - Running: ['***', 'tasks', 'run', 'ingest_star_wars', 'create_people_table', 'scheduled__2022-10-02T14:17:00+00:00', '--job-id', '7', '--raw', '--subdir', 'DAGS_FOLDER/ingest_starwars_data.py', '--cfg-path', '/tmp/tmpydl_40ju', '--error-file', '/tmp/tmpa11sm1we']
[2022-10-03 20:01:14,016] {standard_task_runner.py:77} INFO - Job 7: Subtask create_people_table
[2022-10-03 20:01:14,084] {logging_mixin.py:109} INFO - Running <TaskInstance: ingest_star_wars.create_people_table scheduled__2022-10-02T14:17:00+00:00 [running]> on host 86c7e9112604
[2022-10-03 20:01:14,141] {taskinstance.py:1426} INFO - Exporting the following env vars:
AIRFLOW_CTX_DAG_EMAIL=xxxx@xxxxx.com
AIRFLOW_CTX_DAG_OWNER=Anvesh
AIRFLOW_CTX_DAG_ID=ingest_star_wars
AIRFLOW_CTX_TASK_ID=create_people_table
AIRFLOW_CTX_EXECUTION_DATE=2022-10-02T14:17:00+00:00
AIRFLOW_CTX_DAG_RUN_ID=scheduled__2022-10-02T14:17:00+00:00
[2022-10-03 20:01:14,165] {taskinstance.py:1700} ERROR - Task failed with exception
Traceback (most recent call last):
  File "/home/airflow/.local/lib/python3.7/site-packages/airflow/models/taskinstance.py", line 1329, in _run_raw_task
    self._execute_task_with_callbacks(context)
  File "/home/airflow/.local/lib/python3.7/site-packages/airflow/models/taskinstance.py", line 1455, in _execute_task_with_callbacks
    result = self._execute_task(context, self.task)
  File "/home/airflow/.local/lib/python3.7/site-packages/airflow/models/taskinstance.py", line 1511, in _execute_task
    result = execute_callable(context=context)
  File "/home/airflow/.local/lib/python3.7/site-packages/airflow/providers/postgres/operators/postgres.py", line 69, in execute
    self.hook.run(self.sql, self.autocommit, parameters=self.parameters)
  File "/home/airflow/.local/lib/python3.7/site-packages/airflow/hooks/dbapi.py", line 198, in run
    with closing(self.get_conn()) as conn:
  File "/home/airflow/.local/lib/python3.7/site-packages/airflow/providers/postgres/hooks/postgres.py", line 88, in get_conn
    conn = deepcopy(self.connection or self.get_connection(conn_id))
  File "/home/airflow/.local/lib/python3.7/site-packages/airflow/hooks/base.py", line 68, in get_connection
    conn = Connection.get_connection_from_secrets(conn_id)
  File "/home/airflow/.local/lib/python3.7/site-packages/airflow/models/connection.py", line 410, in get_connection_from_secrets
    raise AirflowNotFoundException(f"The conn_id `{conn_id}` isn't defined")
airflow.exceptions.AirflowNotFoundException: The conn_id `postgres_local` isn't defined
[2022-10-03 20:01:14,175] {taskinstance.py:1277} INFO - Marking task as FAILED. dag_id=ingest_star_wars, task_id=create_people_table, execution_date=20221002T141700, start_date=20221003T200113, end_date=20221003T200114
[2022-10-03 20:01:14,195] {standard_task_runner.py:92} ERROR - Failed to execute job 7 for task create_people_table
Traceback (most recent call last):
  File "/home/airflow/.local/lib/python3.7/site-packages/airflow/task/task_runner/standard_task_runner.py", line 85, in _start_by_fork
    args.func(args, dag=self.dag)
  File "/home/airflow/.local/lib/python3.7/site-packages/airflow/cli/cli_parser.py", line 48, in command
    return func(*args, **kwargs)
  File "/home/airflow/.local/lib/python3.7/site-packages/airflow/utils/cli.py", line 92, in wrapper
    return f(*args, **kwargs)
  File "/home/airflow/.local/lib/python3.7/site-packages/airflow/cli/commands/task_command.py", line 298, in task_run
    _run_task_by_selected_method(args, dag, ti)
  File "/home/airflow/.local/lib/python3.7/site-packages/airflow/cli/commands/task_command.py", line 107, in _run_task_by_selected_method
    _run_raw_task(args, ti)
  File "/home/airflow/.local/lib/python3.7/site-packages/airflow/cli/commands/task_command.py", line 184, in _run_raw_task
    error_file=args.error_file,
  File "/home/airflow/.local/lib/python3.7/site-packages/airflow/utils/session.py", line 70, in wrapper
    return func(*args, session=session, **kwargs)
  File "/home/airflow/.local/lib/python3.7/site-packages/airflow/models/taskinstance.py", line 1329, in _run_raw_task
    self._execute_task_with_callbacks(context)
  File "/home/airflow/.local/lib/python3.7/site-packages/airflow/models/taskinstance.py", line 1455, in _execute_task_with_callbacks
    result = self._execute_task(context, self.task)
  File "/home/airflow/.local/lib/python3.7/site-packages/airflow/models/taskinstance.py", line 1511, in _execute_task
    result = execute_callable(context=context)
  File "/home/airflow/.local/lib/python3.7/site-packages/airflow/providers/postgres/operators/postgres.py", line 69, in execute
    self.hook.run(self.sql, self.autocommit, parameters=self.parameters)
  File "/home/airflow/.local/lib/python3.7/site-packages/airflow/hooks/dbapi.py", line 198, in run
    with closing(self.get_conn()) as conn:
  File "/home/airflow/.local/lib/python3.7/site-packages/airflow/providers/postgres/hooks/postgres.py", line 88, in get_conn
    conn = deepcopy(self.connection or self.get_connection(conn_id))
  File "/home/airflow/.local/lib/python3.7/site-packages/airflow/hooks/base.py", line 68, in get_connection
    conn = Connection.get_connection_from_secrets(conn_id)
  File "/home/airflow/.local/lib/python3.7/site-packages/airflow/models/connection.py", line 410, in get_connection_from_secrets
    raise AirflowNotFoundException(f"The conn_id `{conn_id}` isn't defined")
airflow.exceptions.AirflowNotFoundException: The conn_id `postgres_local` isn't defined
[2022-10-03 20:01:14,227] {local_task_job.py:154} INFO - Task exited with return code 1
[2022-10-03 20:01:14,283] {local_task_job.py:264} INFO - 0 downstream tasks scheduled from follow-on schedule check
