[2022-10-04 12:05:39,095] {taskinstance.py:1032} INFO - Dependencies all met for <TaskInstance: agg_star_wars.wait_for_ingestion manual__2022-10-04T12:05:35.271110+00:00 [queued]>
[2022-10-04 12:05:39,123] {taskinstance.py:1032} INFO - Dependencies all met for <TaskInstance: agg_star_wars.wait_for_ingestion manual__2022-10-04T12:05:35.271110+00:00 [queued]>
[2022-10-04 12:05:39,124] {taskinstance.py:1238} INFO - 
--------------------------------------------------------------------------------
[2022-10-04 12:05:39,125] {taskinstance.py:1239} INFO - Starting attempt 1 of 3
[2022-10-04 12:05:39,126] {taskinstance.py:1240} INFO - 
--------------------------------------------------------------------------------
[2022-10-04 12:05:39,140] {taskinstance.py:1259} INFO - Executing <Task(ExternalTaskSensor): wait_for_ingestion> on 2022-10-04 12:05:37.110100+00:00
[2022-10-04 12:05:39,146] {standard_task_runner.py:52} INFO - Started process 352 to run task
[2022-10-04 12:05:39,160] {standard_task_runner.py:76} INFO - Running: ['***', 'tasks', 'run', 'agg_star_wars', 'wait_for_ingestion', 'manual__2022-10-04T12:05:35.271110+00:00', '--job-id', '29', '--raw', '--subdir', 'DAGS_FOLDER/star_wars_agg.py', '--cfg-path', '/tmp/tmpnj0fwtph', '--error-file', '/tmp/tmpgjpes4nm']
[2022-10-04 12:05:39,163] {standard_task_runner.py:77} INFO - Job 29: Subtask wait_for_ingestion
[2022-10-04 12:05:39,290] {logging_mixin.py:109} INFO - Running <TaskInstance: agg_star_wars.wait_for_ingestion manual__2022-10-04T12:05:35.271110+00:00 [running]> on host be1a5b89e146
[2022-10-04 12:05:39,387] {taskinstance.py:1426} INFO - Exporting the following env vars:
AIRFLOW_CTX_DAG_EMAIL=xxxx@xxxxx.com
AIRFLOW_CTX_DAG_OWNER=Anvesh
AIRFLOW_CTX_DAG_ID=agg_star_wars
AIRFLOW_CTX_TASK_ID=wait_for_ingestion
AIRFLOW_CTX_EXECUTION_DATE=2022-10-04T12:05:37.110100+00:00
AIRFLOW_CTX_DAG_RUN_ID=manual__2022-10-04T12:05:35.271110+00:00
[2022-10-04 12:05:39,389] {warnings.py:110} WARNING - /home/***/.local/lib/python3.7/site-packages/***/utils/context.py:152: AirflowContextDeprecationWarning: Accessing 'execution_date' from the template is deprecated and will be removed in a future version. Please use 'data_interval_start' or 'logical_date' instead.
  warnings.warn(_create_deprecation_warning(key, self._deprecation_replacements[key]))

[2022-10-04 12:05:39,392] {external_task.py:173} INFO - Poking for tasks ['ingestion_success'] in dag ingest_star_wars on 2022-10-04T12:05:37.110100+00:00 ... 
[2022-10-04 12:06:39,472] {external_task.py:173} INFO - Poking for tasks ['ingestion_success'] in dag ingest_star_wars on 2022-10-04T12:05:37.110100+00:00 ... 
[2022-10-04 12:07:39,530] {external_task.py:173} INFO - Poking for tasks ['ingestion_success'] in dag ingest_star_wars on 2022-10-04T12:05:37.110100+00:00 ... 
[2022-10-04 12:08:39,573] {external_task.py:173} INFO - Poking for tasks ['ingestion_success'] in dag ingest_star_wars on 2022-10-04T12:05:37.110100+00:00 ... 
[2022-10-04 12:09:39,660] {external_task.py:173} INFO - Poking for tasks ['ingestion_success'] in dag ingest_star_wars on 2022-10-04T12:05:37.110100+00:00 ... 
[2022-10-04 12:10:39,735] {external_task.py:173} INFO - Poking for tasks ['ingestion_success'] in dag ingest_star_wars on 2022-10-04T12:05:37.110100+00:00 ... 
[2022-10-04 12:10:39,746] {taskinstance.py:1700} ERROR - Task failed with exception
Traceback (most recent call last):
  File "/home/airflow/.local/lib/python3.7/site-packages/airflow/models/taskinstance.py", line 1329, in _run_raw_task
    self._execute_task_with_callbacks(context)
  File "/home/airflow/.local/lib/python3.7/site-packages/airflow/models/taskinstance.py", line 1455, in _execute_task_with_callbacks
    result = self._execute_task(context, self.task)
  File "/home/airflow/.local/lib/python3.7/site-packages/airflow/models/taskinstance.py", line 1511, in _execute_task
    result = execute_callable(context=context)
  File "/home/airflow/.local/lib/python3.7/site-packages/airflow/sensors/base.py", line 240, in execute
    raise AirflowSensorTimeout(f"Snap. Time is OUT. DAG id: {log_dag_id}")
airflow.exceptions.AirflowSensorTimeout: Snap. Time is OUT. DAG id: agg_star_wars
[2022-10-04 12:10:39,766] {taskinstance.py:1277} INFO - Immediate failure requested. Marking task as FAILED. dag_id=agg_star_wars, task_id=wait_for_ingestion, execution_date=20221004T120537, start_date=20221004T120539, end_date=20221004T121039
[2022-10-04 12:10:39,792] {standard_task_runner.py:92} ERROR - Failed to execute job 29 for task wait_for_ingestion
Traceback (most recent call last):
  File "/home/airflow/.local/lib/python3.7/site-packages/airflow/task/task_runner/standard_task_runner.py", line 85, in _start_by_fork
    args.func(args, dag=self.dag)
  File "/home/airflow/.local/lib/python3.7/site-packages/airflow/cli/cli_parser.py", line 48, in command
    return func(*args, **kwargs)
  File "/home/airflow/.local/lib/python3.7/site-packages/airflow/utils/cli.py", line 92, in wrapper
    return f(*args, **kwargs)
  File "/home/airflow/.local/lib/python3.7/site-packages/airflow/cli/commands/task_command.py", line 298, in task_run
    _run_task_by_selected_method(args, dag, ti)
  File "/home/airflow/.local/lib/python3.7/site-packages/airflow/cli/commands/task_command.py", line 107, in _run_task_by_selected_method
    _run_raw_task(args, ti)
  File "/home/airflow/.local/lib/python3.7/site-packages/airflow/cli/commands/task_command.py", line 184, in _run_raw_task
    error_file=args.error_file,
  File "/home/airflow/.local/lib/python3.7/site-packages/airflow/utils/session.py", line 70, in wrapper
    return func(*args, session=session, **kwargs)
  File "/home/airflow/.local/lib/python3.7/site-packages/airflow/models/taskinstance.py", line 1329, in _run_raw_task
    self._execute_task_with_callbacks(context)
  File "/home/airflow/.local/lib/python3.7/site-packages/airflow/models/taskinstance.py", line 1455, in _execute_task_with_callbacks
    result = self._execute_task(context, self.task)
  File "/home/airflow/.local/lib/python3.7/site-packages/airflow/models/taskinstance.py", line 1511, in _execute_task
    result = execute_callable(context=context)
  File "/home/airflow/.local/lib/python3.7/site-packages/airflow/sensors/base.py", line 240, in execute
    raise AirflowSensorTimeout(f"Snap. Time is OUT. DAG id: {log_dag_id}")
airflow.exceptions.AirflowSensorTimeout: Snap. Time is OUT. DAG id: agg_star_wars
[2022-10-04 12:10:39,840] {local_task_job.py:154} INFO - Task exited with return code 1
[2022-10-04 12:10:39,878] {local_task_job.py:264} INFO - 0 downstream tasks scheduled from follow-on schedule check
