[2022-10-03 20:36:43,773] {taskinstance.py:1032} INFO - Dependencies all met for <TaskInstance: ingest_star_wars.create_films_table scheduled__2022-10-03T00:00:00+00:00 [queued]>
[2022-10-03 20:36:43,867] {taskinstance.py:1032} INFO - Dependencies all met for <TaskInstance: ingest_star_wars.create_films_table scheduled__2022-10-03T00:00:00+00:00 [queued]>
[2022-10-03 20:36:43,879] {taskinstance.py:1238} INFO - 
--------------------------------------------------------------------------------
[2022-10-03 20:36:43,881] {taskinstance.py:1239} INFO - Starting attempt 1 of 1
[2022-10-03 20:36:43,882] {taskinstance.py:1240} INFO - 
--------------------------------------------------------------------------------
[2022-10-03 20:36:43,949] {taskinstance.py:1259} INFO - Executing <Task(PostgresOperator): create_films_table> on 2022-10-03 00:00:00+00:00
[2022-10-03 20:36:43,963] {standard_task_runner.py:52} INFO - Started process 1718 to run task
[2022-10-03 20:36:43,990] {standard_task_runner.py:76} INFO - Running: ['***', 'tasks', 'run', 'ingest_star_wars', 'create_films_table', 'scheduled__2022-10-03T00:00:00+00:00', '--job-id', '10', '--raw', '--subdir', 'DAGS_FOLDER/ingest_starwars_data.py', '--cfg-path', '/tmp/tmpvxxqgsy0', '--error-file', '/tmp/tmpzc2t25ri']
[2022-10-03 20:36:44,001] {standard_task_runner.py:77} INFO - Job 10: Subtask create_films_table
[2022-10-03 20:36:44,225] {logging_mixin.py:109} INFO - Running <TaskInstance: ingest_star_wars.create_films_table scheduled__2022-10-03T00:00:00+00:00 [running]> on host 86c7e9112604
[2022-10-03 20:36:44,345] {taskinstance.py:1426} INFO - Exporting the following env vars:
AIRFLOW_CTX_DAG_EMAIL=xxxx@xxxxx.com
AIRFLOW_CTX_DAG_OWNER=Ram
AIRFLOW_CTX_DAG_ID=ingest_star_wars
AIRFLOW_CTX_TASK_ID=create_films_table
AIRFLOW_CTX_EXECUTION_DATE=2022-10-03T00:00:00+00:00
AIRFLOW_CTX_DAG_RUN_ID=scheduled__2022-10-03T00:00:00+00:00
[2022-10-03 20:36:44,362] {base.py:79} INFO - Using connection to: id: postgres_local. Host: host.docker.internal, Port: 5432, Schema: public, Login: postgres, Password: ***, extra: {}
[2022-10-03 20:36:44,426] {taskinstance.py:1700} ERROR - Task failed with exception
Traceback (most recent call last):
  File "/home/airflow/.local/lib/python3.7/site-packages/airflow/models/taskinstance.py", line 1329, in _run_raw_task
    self._execute_task_with_callbacks(context)
  File "/home/airflow/.local/lib/python3.7/site-packages/airflow/models/taskinstance.py", line 1455, in _execute_task_with_callbacks
    result = self._execute_task(context, self.task)
  File "/home/airflow/.local/lib/python3.7/site-packages/airflow/models/taskinstance.py", line 1511, in _execute_task
    result = execute_callable(context=context)
  File "/home/airflow/.local/lib/python3.7/site-packages/airflow/providers/postgres/operators/postgres.py", line 69, in execute
    self.hook.run(self.sql, self.autocommit, parameters=self.parameters)
  File "/home/airflow/.local/lib/python3.7/site-packages/airflow/hooks/dbapi.py", line 198, in run
    with closing(self.get_conn()) as conn:
  File "/home/airflow/.local/lib/python3.7/site-packages/airflow/providers/postgres/hooks/postgres.py", line 115, in get_conn
    self.conn = psycopg2.connect(**conn_args)
  File "/home/airflow/.local/lib/python3.7/site-packages/psycopg2/__init__.py", line 122, in connect
    conn = _connect(dsn, connection_factory=connection_factory, **kwasync)
psycopg2.OperationalError: connection to server at "host.docker.internal" (192.168.65.2), port 5432 failed: FATAL:  database "public" does not exist

[2022-10-03 20:36:44,454] {taskinstance.py:1277} INFO - Marking task as FAILED. dag_id=ingest_star_wars, task_id=create_films_table, execution_date=20221003T000000, start_date=20221003T203643, end_date=20221003T203644
[2022-10-03 20:36:44,509] {standard_task_runner.py:92} ERROR - Failed to execute job 10 for task create_films_table
Traceback (most recent call last):
  File "/home/airflow/.local/lib/python3.7/site-packages/airflow/task/task_runner/standard_task_runner.py", line 85, in _start_by_fork
    args.func(args, dag=self.dag)
  File "/home/airflow/.local/lib/python3.7/site-packages/airflow/cli/cli_parser.py", line 48, in command
    return func(*args, **kwargs)
  File "/home/airflow/.local/lib/python3.7/site-packages/airflow/utils/cli.py", line 92, in wrapper
    return f(*args, **kwargs)
  File "/home/airflow/.local/lib/python3.7/site-packages/airflow/cli/commands/task_command.py", line 298, in task_run
    _run_task_by_selected_method(args, dag, ti)
  File "/home/airflow/.local/lib/python3.7/site-packages/airflow/cli/commands/task_command.py", line 107, in _run_task_by_selected_method
    _run_raw_task(args, ti)
  File "/home/airflow/.local/lib/python3.7/site-packages/airflow/cli/commands/task_command.py", line 184, in _run_raw_task
    error_file=args.error_file,
  File "/home/airflow/.local/lib/python3.7/site-packages/airflow/utils/session.py", line 70, in wrapper
    return func(*args, session=session, **kwargs)
  File "/home/airflow/.local/lib/python3.7/site-packages/airflow/models/taskinstance.py", line 1329, in _run_raw_task
    self._execute_task_with_callbacks(context)
  File "/home/airflow/.local/lib/python3.7/site-packages/airflow/models/taskinstance.py", line 1455, in _execute_task_with_callbacks
    result = self._execute_task(context, self.task)
  File "/home/airflow/.local/lib/python3.7/site-packages/airflow/models/taskinstance.py", line 1511, in _execute_task
    result = execute_callable(context=context)
  File "/home/airflow/.local/lib/python3.7/site-packages/airflow/providers/postgres/operators/postgres.py", line 69, in execute
    self.hook.run(self.sql, self.autocommit, parameters=self.parameters)
  File "/home/airflow/.local/lib/python3.7/site-packages/airflow/hooks/dbapi.py", line 198, in run
    with closing(self.get_conn()) as conn:
  File "/home/airflow/.local/lib/python3.7/site-packages/airflow/providers/postgres/hooks/postgres.py", line 115, in get_conn
    self.conn = psycopg2.connect(**conn_args)
  File "/home/airflow/.local/lib/python3.7/site-packages/psycopg2/__init__.py", line 122, in connect
    conn = _connect(dsn, connection_factory=connection_factory, **kwasync)
psycopg2.OperationalError: connection to server at "host.docker.internal" (192.168.65.2), port 5432 failed: FATAL:  database "public" does not exist

[2022-10-03 20:36:44,605] {local_task_job.py:154} INFO - Task exited with return code 1
[2022-10-03 20:36:44,783] {local_task_job.py:264} INFO - 0 downstream tasks scheduled from follow-on schedule check
[2022-10-04 13:29:43,491] {taskinstance.py:1032} INFO - Dependencies all met for <TaskInstance: ingest_star_wars.create_films_table scheduled__2022-10-03T00:00:00+00:00 [queued]>
[2022-10-04 13:29:43,506] {taskinstance.py:1032} INFO - Dependencies all met for <TaskInstance: ingest_star_wars.create_films_table scheduled__2022-10-03T00:00:00+00:00 [queued]>
[2022-10-04 13:29:43,507] {taskinstance.py:1238} INFO - 
--------------------------------------------------------------------------------
[2022-10-04 13:29:43,508] {taskinstance.py:1239} INFO - Starting attempt 1 of 1
[2022-10-04 13:29:43,509] {taskinstance.py:1240} INFO - 
--------------------------------------------------------------------------------
[2022-10-04 13:29:43,537] {taskinstance.py:1259} INFO - Executing <Task(PostgresOperator): create_films_table> on 2022-10-03 00:00:00+00:00
[2022-10-04 13:29:43,545] {standard_task_runner.py:52} INFO - Started process 3876 to run task
[2022-10-04 13:29:43,561] {standard_task_runner.py:76} INFO - Running: ['***', 'tasks', 'run', 'ingest_star_wars', 'create_films_table', 'scheduled__2022-10-03T00:00:00+00:00', '--job-id', '40', '--raw', '--subdir', 'DAGS_FOLDER/ingest_starwars_data.py', '--cfg-path', '/tmp/tmp9t27kglw', '--error-file', '/tmp/tmp_0q1ik_1']
[2022-10-04 13:29:43,563] {standard_task_runner.py:77} INFO - Job 40: Subtask create_films_table
[2022-10-04 13:29:43,655] {logging_mixin.py:109} INFO - Running <TaskInstance: ingest_star_wars.create_films_table scheduled__2022-10-03T00:00:00+00:00 [running]> on host be1a5b89e146
[2022-10-04 13:29:43,757] {taskinstance.py:1426} INFO - Exporting the following env vars:
AIRFLOW_CTX_DAG_EMAIL=xxxx@xxxxx.com
AIRFLOW_CTX_DAG_OWNER=Ram
AIRFLOW_CTX_DAG_ID=ingest_star_wars
AIRFLOW_CTX_TASK_ID=create_films_table
AIRFLOW_CTX_EXECUTION_DATE=2022-10-03T00:00:00+00:00
AIRFLOW_CTX_DAG_RUN_ID=scheduled__2022-10-03T00:00:00+00:00
[2022-10-04 13:29:43,775] {base.py:79} INFO - Using connection to: id: postgres_local. Host: host.docker.internal, Port: 5432, Schema: postgres, Login: postgres, Password: ***, extra: {}
[2022-10-04 13:29:43,847] {dbapi.py:225} INFO - Running statement: CREATE TABLE IF NOT EXISTS star_wars_films (
            title TEXT,
            episode_id TEXT,
            opening_crawl TEXT,
            director TEXT,
            producer TEXT,
            release_date TEXT,
            characters TEXT,
            planets TEXT,
            starships TEXT,
            vehicles TEXT,
            species TEXT,
            created TEXT,
            edited TEXT,
            url TEXT
            );, parameters: None
[2022-10-04 13:29:43,853] {postgres.py:71} INFO - NOTICE:  relation "star_wars_films" already exists, skipping

[2022-10-04 13:29:43,868] {taskinstance.py:1277} INFO - Marking task as SUCCESS. dag_id=ingest_star_wars, task_id=create_films_table, execution_date=20221003T000000, start_date=20221004T132943, end_date=20221004T132943
[2022-10-04 13:29:43,926] {local_task_job.py:154} INFO - Task exited with return code 0
[2022-10-04 13:29:43,991] {local_task_job.py:264} INFO - 1 downstream tasks scheduled from follow-on schedule check
