[2022-10-03 20:01:04,103] {taskinstance.py:1032} INFO - Dependencies all met for <TaskInstance: agg_star_wars.wait_for_ingestion scheduled__2022-10-02T14:17:00+00:00 [queued]>
[2022-10-03 20:01:04,142] {taskinstance.py:1032} INFO - Dependencies all met for <TaskInstance: agg_star_wars.wait_for_ingestion scheduled__2022-10-02T14:17:00+00:00 [queued]>
[2022-10-03 20:01:04,150] {taskinstance.py:1238} INFO - 
--------------------------------------------------------------------------------
[2022-10-03 20:01:04,153] {taskinstance.py:1239} INFO - Starting attempt 1 of 3
[2022-10-03 20:01:04,154] {taskinstance.py:1240} INFO - 
--------------------------------------------------------------------------------
[2022-10-03 20:01:04,206] {taskinstance.py:1259} INFO - Executing <Task(ExternalTaskSensor): wait_for_ingestion> on 2022-10-02 14:17:00+00:00
[2022-10-03 20:01:04,258] {standard_task_runner.py:76} INFO - Running: ['***', 'tasks', 'run', 'agg_star_wars', 'wait_for_ingestion', 'scheduled__2022-10-02T14:17:00+00:00', '--job-id', '3', '--raw', '--subdir', 'DAGS_FOLDER/star_wars_agg.py', '--cfg-path', '/tmp/tmpkumisi57', '--error-file', '/tmp/tmp2os6nzml']
[2022-10-03 20:01:04,247] {standard_task_runner.py:52} INFO - Started process 239 to run task
[2022-10-03 20:01:04,265] {standard_task_runner.py:77} INFO - Job 3: Subtask wait_for_ingestion
[2022-10-03 20:01:04,426] {logging_mixin.py:109} INFO - Running <TaskInstance: agg_star_wars.wait_for_ingestion scheduled__2022-10-02T14:17:00+00:00 [running]> on host 86c7e9112604
[2022-10-03 20:01:04,633] {taskinstance.py:1426} INFO - Exporting the following env vars:
AIRFLOW_CTX_DAG_EMAIL=xxxx@xxxxx.com
AIRFLOW_CTX_DAG_OWNER=Anvesh
AIRFLOW_CTX_DAG_ID=agg_star_wars
AIRFLOW_CTX_TASK_ID=wait_for_ingestion
AIRFLOW_CTX_EXECUTION_DATE=2022-10-02T14:17:00+00:00
AIRFLOW_CTX_DAG_RUN_ID=scheduled__2022-10-02T14:17:00+00:00
[2022-10-03 20:01:04,636] {warnings.py:110} WARNING - /home/***/.local/lib/python3.7/site-packages/***/utils/context.py:152: AirflowContextDeprecationWarning: Accessing 'execution_date' from the template is deprecated and will be removed in a future version. Please use 'data_interval_start' or 'logical_date' instead.
  warnings.warn(_create_deprecation_warning(key, self._deprecation_replacements[key]))

[2022-10-03 20:01:04,638] {external_task.py:173} INFO - Poking for tasks ['ingestion_success'] in dag ingest_star_wars on 2022-10-02T14:17:00+00:00 ... 
[2022-10-03 20:02:04,737] {external_task.py:173} INFO - Poking for tasks ['ingestion_success'] in dag ingest_star_wars on 2022-10-02T14:17:00+00:00 ... 
[2022-10-03 20:03:04,862] {external_task.py:173} INFO - Poking for tasks ['ingestion_success'] in dag ingest_star_wars on 2022-10-02T14:17:00+00:00 ... 
[2022-10-03 20:04:04,937] {external_task.py:173} INFO - Poking for tasks ['ingestion_success'] in dag ingest_star_wars on 2022-10-02T14:17:00+00:00 ... 
[2022-10-03 20:05:05,005] {external_task.py:173} INFO - Poking for tasks ['ingestion_success'] in dag ingest_star_wars on 2022-10-02T14:17:00+00:00 ... 
[2022-10-03 20:06:05,087] {external_task.py:173} INFO - Poking for tasks ['ingestion_success'] in dag ingest_star_wars on 2022-10-02T14:17:00+00:00 ... 
[2022-10-03 20:06:05,102] {taskinstance.py:1700} ERROR - Task failed with exception
Traceback (most recent call last):
  File "/home/airflow/.local/lib/python3.7/site-packages/airflow/models/taskinstance.py", line 1329, in _run_raw_task
    self._execute_task_with_callbacks(context)
  File "/home/airflow/.local/lib/python3.7/site-packages/airflow/models/taskinstance.py", line 1455, in _execute_task_with_callbacks
    result = self._execute_task(context, self.task)
  File "/home/airflow/.local/lib/python3.7/site-packages/airflow/models/taskinstance.py", line 1511, in _execute_task
    result = execute_callable(context=context)
  File "/home/airflow/.local/lib/python3.7/site-packages/airflow/sensors/base.py", line 240, in execute
    raise AirflowSensorTimeout(f"Snap. Time is OUT. DAG id: {log_dag_id}")
airflow.exceptions.AirflowSensorTimeout: Snap. Time is OUT. DAG id: agg_star_wars
[2022-10-03 20:06:05,120] {taskinstance.py:1277} INFO - Immediate failure requested. Marking task as FAILED. dag_id=agg_star_wars, task_id=wait_for_ingestion, execution_date=20221002T141700, start_date=20221003T200104, end_date=20221003T200605
[2022-10-03 20:06:05,140] {standard_task_runner.py:92} ERROR - Failed to execute job 3 for task wait_for_ingestion
Traceback (most recent call last):
  File "/home/airflow/.local/lib/python3.7/site-packages/airflow/task/task_runner/standard_task_runner.py", line 85, in _start_by_fork
    args.func(args, dag=self.dag)
  File "/home/airflow/.local/lib/python3.7/site-packages/airflow/cli/cli_parser.py", line 48, in command
    return func(*args, **kwargs)
  File "/home/airflow/.local/lib/python3.7/site-packages/airflow/utils/cli.py", line 92, in wrapper
    return f(*args, **kwargs)
  File "/home/airflow/.local/lib/python3.7/site-packages/airflow/cli/commands/task_command.py", line 298, in task_run
    _run_task_by_selected_method(args, dag, ti)
  File "/home/airflow/.local/lib/python3.7/site-packages/airflow/cli/commands/task_command.py", line 107, in _run_task_by_selected_method
    _run_raw_task(args, ti)
  File "/home/airflow/.local/lib/python3.7/site-packages/airflow/cli/commands/task_command.py", line 184, in _run_raw_task
    error_file=args.error_file,
  File "/home/airflow/.local/lib/python3.7/site-packages/airflow/utils/session.py", line 70, in wrapper
    return func(*args, session=session, **kwargs)
  File "/home/airflow/.local/lib/python3.7/site-packages/airflow/models/taskinstance.py", line 1329, in _run_raw_task
    self._execute_task_with_callbacks(context)
  File "/home/airflow/.local/lib/python3.7/site-packages/airflow/models/taskinstance.py", line 1455, in _execute_task_with_callbacks
    result = self._execute_task(context, self.task)
  File "/home/airflow/.local/lib/python3.7/site-packages/airflow/models/taskinstance.py", line 1511, in _execute_task
    result = execute_callable(context=context)
  File "/home/airflow/.local/lib/python3.7/site-packages/airflow/sensors/base.py", line 240, in execute
    raise AirflowSensorTimeout(f"Snap. Time is OUT. DAG id: {log_dag_id}")
airflow.exceptions.AirflowSensorTimeout: Snap. Time is OUT. DAG id: agg_star_wars
[2022-10-03 20:06:05,179] {local_task_job.py:154} INFO - Task exited with return code 1
[2022-10-03 20:06:05,227] {local_task_job.py:264} INFO - 0 downstream tasks scheduled from follow-on schedule check
[2022-10-03 20:35:58,901] {taskinstance.py:1032} INFO - Dependencies all met for <TaskInstance: agg_star_wars.wait_for_ingestion scheduled__2022-10-02T14:17:00+00:00 [queued]>
[2022-10-03 20:35:58,912] {taskinstance.py:1032} INFO - Dependencies all met for <TaskInstance: agg_star_wars.wait_for_ingestion scheduled__2022-10-02T14:17:00+00:00 [queued]>
[2022-10-03 20:35:58,913] {taskinstance.py:1238} INFO - 
--------------------------------------------------------------------------------
[2022-10-03 20:35:58,914] {taskinstance.py:1239} INFO - Starting attempt 1 of 3
[2022-10-03 20:35:58,915] {taskinstance.py:1240} INFO - 
--------------------------------------------------------------------------------
[2022-10-03 20:35:58,928] {taskinstance.py:1259} INFO - Executing <Task(ExternalTaskSensor): wait_for_ingestion> on 2022-10-02 14:17:00+00:00
[2022-10-03 20:35:58,933] {standard_task_runner.py:52} INFO - Started process 1683 to run task
[2022-10-03 20:35:58,937] {standard_task_runner.py:76} INFO - Running: ['***', 'tasks', 'run', 'agg_star_wars', 'wait_for_ingestion', 'scheduled__2022-10-02T14:17:00+00:00', '--job-id', '8', '--raw', '--subdir', 'DAGS_FOLDER/star_wars_agg.py', '--cfg-path', '/tmp/tmpqkekjxqe', '--error-file', '/tmp/tmp0jzw_9r6']
[2022-10-03 20:35:58,939] {standard_task_runner.py:77} INFO - Job 8: Subtask wait_for_ingestion
[2022-10-03 20:35:58,995] {logging_mixin.py:109} INFO - Running <TaskInstance: agg_star_wars.wait_for_ingestion scheduled__2022-10-02T14:17:00+00:00 [running]> on host 86c7e9112604
[2022-10-03 20:35:59,047] {taskinstance.py:1426} INFO - Exporting the following env vars:
AIRFLOW_CTX_DAG_EMAIL=xxxx@xxxxx.com
AIRFLOW_CTX_DAG_OWNER=Anvesh
AIRFLOW_CTX_DAG_ID=agg_star_wars
AIRFLOW_CTX_TASK_ID=wait_for_ingestion
AIRFLOW_CTX_EXECUTION_DATE=2022-10-02T14:17:00+00:00
AIRFLOW_CTX_DAG_RUN_ID=scheduled__2022-10-02T14:17:00+00:00
[2022-10-03 20:35:59,049] {warnings.py:110} WARNING - /home/***/.local/lib/python3.7/site-packages/***/utils/context.py:152: AirflowContextDeprecationWarning: Accessing 'execution_date' from the template is deprecated and will be removed in a future version. Please use 'data_interval_start' or 'logical_date' instead.
  warnings.warn(_create_deprecation_warning(key, self._deprecation_replacements[key]))

[2022-10-03 20:35:59,050] {external_task.py:173} INFO - Poking for tasks ['ingestion_success'] in dag ingest_star_wars on 2022-10-02T14:17:00+00:00 ... 
[2022-10-03 20:36:59,122] {external_task.py:173} INFO - Poking for tasks ['ingestion_success'] in dag ingest_star_wars on 2022-10-02T14:17:00+00:00 ... 
[2022-10-03 20:37:59,194] {external_task.py:173} INFO - Poking for tasks ['ingestion_success'] in dag ingest_star_wars on 2022-10-02T14:17:00+00:00 ... 
[2022-10-03 20:38:59,242] {external_task.py:173} INFO - Poking for tasks ['ingestion_success'] in dag ingest_star_wars on 2022-10-02T14:17:00+00:00 ... 
[2022-10-03 20:39:59,282] {external_task.py:173} INFO - Poking for tasks ['ingestion_success'] in dag ingest_star_wars on 2022-10-02T14:17:00+00:00 ... 
[2022-10-03 20:40:59,365] {external_task.py:173} INFO - Poking for tasks ['ingestion_success'] in dag ingest_star_wars on 2022-10-02T14:17:00+00:00 ... 
[2022-10-03 20:40:59,578] {taskinstance.py:1700} ERROR - Task failed with exception
Traceback (most recent call last):
  File "/home/airflow/.local/lib/python3.7/site-packages/airflow/models/taskinstance.py", line 1329, in _run_raw_task
    self._execute_task_with_callbacks(context)
  File "/home/airflow/.local/lib/python3.7/site-packages/airflow/models/taskinstance.py", line 1455, in _execute_task_with_callbacks
    result = self._execute_task(context, self.task)
  File "/home/airflow/.local/lib/python3.7/site-packages/airflow/models/taskinstance.py", line 1511, in _execute_task
    result = execute_callable(context=context)
  File "/home/airflow/.local/lib/python3.7/site-packages/airflow/sensors/base.py", line 240, in execute
    raise AirflowSensorTimeout(f"Snap. Time is OUT. DAG id: {log_dag_id}")
airflow.exceptions.AirflowSensorTimeout: Snap. Time is OUT. DAG id: agg_star_wars
[2022-10-03 20:40:59,785] {taskinstance.py:1277} INFO - Immediate failure requested. Marking task as FAILED. dag_id=agg_star_wars, task_id=wait_for_ingestion, execution_date=20221002T141700, start_date=20221003T203558, end_date=20221003T204059
[2022-10-03 20:41:00,127] {standard_task_runner.py:92} ERROR - Failed to execute job 8 for task wait_for_ingestion
Traceback (most recent call last):
  File "/home/airflow/.local/lib/python3.7/site-packages/airflow/task/task_runner/standard_task_runner.py", line 85, in _start_by_fork
    args.func(args, dag=self.dag)
  File "/home/airflow/.local/lib/python3.7/site-packages/airflow/cli/cli_parser.py", line 48, in command
    return func(*args, **kwargs)
  File "/home/airflow/.local/lib/python3.7/site-packages/airflow/utils/cli.py", line 92, in wrapper
    return f(*args, **kwargs)
  File "/home/airflow/.local/lib/python3.7/site-packages/airflow/cli/commands/task_command.py", line 298, in task_run
    _run_task_by_selected_method(args, dag, ti)
  File "/home/airflow/.local/lib/python3.7/site-packages/airflow/cli/commands/task_command.py", line 107, in _run_task_by_selected_method
    _run_raw_task(args, ti)
  File "/home/airflow/.local/lib/python3.7/site-packages/airflow/cli/commands/task_command.py", line 184, in _run_raw_task
    error_file=args.error_file,
  File "/home/airflow/.local/lib/python3.7/site-packages/airflow/utils/session.py", line 70, in wrapper
    return func(*args, session=session, **kwargs)
  File "/home/airflow/.local/lib/python3.7/site-packages/airflow/models/taskinstance.py", line 1329, in _run_raw_task
    self._execute_task_with_callbacks(context)
  File "/home/airflow/.local/lib/python3.7/site-packages/airflow/models/taskinstance.py", line 1455, in _execute_task_with_callbacks
    result = self._execute_task(context, self.task)
  File "/home/airflow/.local/lib/python3.7/site-packages/airflow/models/taskinstance.py", line 1511, in _execute_task
    result = execute_callable(context=context)
  File "/home/airflow/.local/lib/python3.7/site-packages/airflow/sensors/base.py", line 240, in execute
    raise AirflowSensorTimeout(f"Snap. Time is OUT. DAG id: {log_dag_id}")
airflow.exceptions.AirflowSensorTimeout: Snap. Time is OUT. DAG id: agg_star_wars
[2022-10-03 20:41:00,230] {local_task_job.py:154} INFO - Task exited with return code 1
[2022-10-03 20:41:00,597] {local_task_job.py:264} INFO - 0 downstream tasks scheduled from follow-on schedule check
